2018-06-16 15:30:21,443 INFO: Microblog Startup [in /home/giddy/Desktop/microblog/app/__init__.py:41
2018-06-16 16:21:53,746 INFO: Microblog Startup [in /home/giddy/Desktop/microblog/app/__init__.py:41
2018-06-19 13:49:25,723 INFO: Microblog Startup [in /home/giddy/Desktop/microblog/app/__init__.py:41
2018-06-19 13:49:48,611 ERROR: Exception on /follow/sol [GET] [in /home/giddy/Desktop/microblog/venv/lib/python3.4/site-packages/flask/app.py:1761
Traceback (most recent call last):
  File "/home/giddy/Desktop/microblog/venv/lib/python3.4/site-packages/flask/app.py", line 2292, in wsgi_app
    response = self.full_dispatch_request()
  File "/home/giddy/Desktop/microblog/venv/lib/python3.4/site-packages/flask/app.py", line 1816, in full_dispatch_request
    return self.finalize_request(rv)
  File "/home/giddy/Desktop/microblog/venv/lib/python3.4/site-packages/flask/app.py", line 1831, in finalize_request
    response = self.make_response(rv)
  File "/home/giddy/Desktop/microblog/venv/lib/python3.4/site-packages/flask/app.py", line 1957, in make_response
    'The view function did not return a valid response. The'
TypeError: The view function did not return a valid response. The function either returned None or ended without a return statement.
2018-06-19 13:53:47,726 INFO: Microblog Startup [in /home/giddy/Desktop/microblog/app/__init__.py:41
2018-06-19 15:56:43,307 INFO: Microblog Startup [in /home/giddy/Desktop/microblog/app/__init__.py:41
2018-06-19 15:57:28,731 ERROR: Exception on /follow/sol [GET] [in /home/giddy/Desktop/microblog/venv/lib/python3.4/site-packages/flask/app.py:1761
Traceback (most recent call last):
  File "/home/giddy/Desktop/microblog/venv/lib/python3.4/site-packages/flask/app.py", line 2292, in wsgi_app
    response = self.full_dispatch_request()
  File "/home/giddy/Desktop/microblog/venv/lib/python3.4/site-packages/flask/app.py", line 1816, in full_dispatch_request
    return self.finalize_request(rv)
  File "/home/giddy/Desktop/microblog/venv/lib/python3.4/site-packages/flask/app.py", line 1831, in finalize_request
    response = self.make_response(rv)
  File "/home/giddy/Desktop/microblog/venv/lib/python3.4/site-packages/flask/app.py", line 1957, in make_response
    'The view function did not return a valid response. The'
TypeError: The view function did not return a valid response. The function either returned None or ended without a return statement.
2018-06-19 20:22:37,745 INFO: Microblog Startup [in /home/giddy/Desktop/microblog/app/__init__.py:41
2018-06-19 20:23:01,429 INFO: Microblog Startup [in /home/giddy/Desktop/microblog/app/__init__.py:41
2018-06-19 20:23:40,867 INFO: Microblog Startup [in /home/giddy/Desktop/microblog/app/__init__.py:41
2018-06-21 13:42:02,580 INFO: Microblog Startup [in /home/giddy/Desktop/microblog/app/__init__.py:44
2018-06-21 16:44:36,286 INFO: Microblog Startup [in /home/giddy/Desktop/microblog/app/__init__.py:44
2018-06-21 16:46:33,651 ERROR: Exception on /reset_password [GET] [in /home/giddy/Desktop/microblog/venv/lib/python3.4/site-packages/flask/app.py:1761
Traceback (most recent call last):
  File "/home/giddy/Desktop/microblog/venv/lib/python3.4/site-packages/flask/app.py", line 2292, in wsgi_app
    response = self.full_dispatch_request()
  File "/home/giddy/Desktop/microblog/venv/lib/python3.4/site-packages/flask/app.py", line 1815, in full_dispatch_request
    rv = self.handle_user_exception(e)
  File "/home/giddy/Desktop/microblog/venv/lib/python3.4/site-packages/flask/app.py", line 1718, in handle_user_exception
    reraise(exc_type, exc_value, tb)
  File "/home/giddy/Desktop/microblog/venv/lib/python3.4/site-packages/flask/_compat.py", line 35, in reraise
    raise value
  File "/home/giddy/Desktop/microblog/venv/lib/python3.4/site-packages/flask/app.py", line 1813, in full_dispatch_request
    rv = self.dispatch_request()
  File "/home/giddy/Desktop/microblog/venv/lib/python3.4/site-packages/flask/app.py", line 1799, in dispatch_request
    return self.view_functions[rule.endpoint](**req.view_args)
TypeError: reset_password() missing 1 required positional argument: 'token'
2018-06-21 16:46:51,304 ERROR: Exception on /reset_password [GET] [in /home/giddy/Desktop/microblog/venv/lib/python3.4/site-packages/flask/app.py:1761
Traceback (most recent call last):
  File "/home/giddy/Desktop/microblog/venv/lib/python3.4/site-packages/flask/app.py", line 2292, in wsgi_app
    response = self.full_dispatch_request()
  File "/home/giddy/Desktop/microblog/venv/lib/python3.4/site-packages/flask/app.py", line 1815, in full_dispatch_request
    rv = self.handle_user_exception(e)
  File "/home/giddy/Desktop/microblog/venv/lib/python3.4/site-packages/flask/app.py", line 1718, in handle_user_exception
    reraise(exc_type, exc_value, tb)
  File "/home/giddy/Desktop/microblog/venv/lib/python3.4/site-packages/flask/_compat.py", line 35, in reraise
    raise value
  File "/home/giddy/Desktop/microblog/venv/lib/python3.4/site-packages/flask/app.py", line 1813, in full_dispatch_request
    rv = self.dispatch_request()
  File "/home/giddy/Desktop/microblog/venv/lib/python3.4/site-packages/flask/app.py", line 1799, in dispatch_request
    return self.view_functions[rule.endpoint](**req.view_args)
TypeError: reset_password() missing 1 required positional argument: 'token'
2018-06-21 16:56:24,703 INFO: Microblog Startup [in /home/giddy/Desktop/microblog/app/__init__.py:44
2018-06-21 16:57:14,248 ERROR: Exception on /reset_password/eyJhbGciOiJIUzI1NiIsInR5cCI6IkpXVCJ9.eyJyZXNldCBwYXNzd29yZCI6MSwiZXhwIjoxNTI5NTkwMDA0LjM1Mzc5Nzd9.SjPyviwHATFfm1FzPn33lF3U_JHIDgmRsgGd47v0bFc [GET] [in /home/giddy/Desktop/microblog/venv/lib/python3.4/site-packages/flask/app.py:1761
Traceback (most recent call last):
  File "/home/giddy/Desktop/microblog/venv/lib/python3.4/site-packages/flask/app.py", line 2292, in wsgi_app
    response = self.full_dispatch_request()
  File "/home/giddy/Desktop/microblog/venv/lib/python3.4/site-packages/flask/app.py", line 1815, in full_dispatch_request
    rv = self.handle_user_exception(e)
  File "/home/giddy/Desktop/microblog/venv/lib/python3.4/site-packages/flask/app.py", line 1718, in handle_user_exception
    reraise(exc_type, exc_value, tb)
  File "/home/giddy/Desktop/microblog/venv/lib/python3.4/site-packages/flask/_compat.py", line 35, in reraise
    raise value
  File "/home/giddy/Desktop/microblog/venv/lib/python3.4/site-packages/flask/app.py", line 1813, in full_dispatch_request
    rv = self.dispatch_request()
  File "/home/giddy/Desktop/microblog/venv/lib/python3.4/site-packages/flask/app.py", line 1799, in dispatch_request
    return self.view_functions[rule.endpoint](**req.view_args)
  File "/home/giddy/Desktop/microblog/app/routes.py", line 103, in reset_password
    user = User.verify_reset_password_token(token)
AttributeError: type object 'User' has no attribute 'verify_reset_password_token'
2018-06-21 17:00:22,637 INFO: Microblog Startup [in /home/giddy/Desktop/microblog/app/__init__.py:44
2018-06-21 17:01:24,489 ERROR: Exception on /reset_password/eyJhbGciOiJIUzI1NiIsInR5cCI6IkpXVCJ9.eyJyZXNldCBwYXNzd29yZCI6MSwiZXhwIjoxNTI5NTkwMjY1LjQ1MjUyMDF9.zKauiSwuNvTwgVUXzPMhYK07pBvv3q_FW-OPndZ8eL0 [GET] [in /home/giddy/Desktop/microblog/venv/lib/python3.4/site-packages/flask/app.py:1761
Traceback (most recent call last):
  File "/home/giddy/Desktop/microblog/venv/lib/python3.4/site-packages/flask/app.py", line 2292, in wsgi_app
    response = self.full_dispatch_request()
  File "/home/giddy/Desktop/microblog/venv/lib/python3.4/site-packages/flask/app.py", line 1815, in full_dispatch_request
    rv = self.handle_user_exception(e)
  File "/home/giddy/Desktop/microblog/venv/lib/python3.4/site-packages/flask/app.py", line 1718, in handle_user_exception
    reraise(exc_type, exc_value, tb)
  File "/home/giddy/Desktop/microblog/venv/lib/python3.4/site-packages/flask/_compat.py", line 35, in reraise
    raise value
  File "/home/giddy/Desktop/microblog/venv/lib/python3.4/site-packages/flask/app.py", line 1813, in full_dispatch_request
    rv = self.dispatch_request()
  File "/home/giddy/Desktop/microblog/venv/lib/python3.4/site-packages/flask/app.py", line 1799, in dispatch_request
    return self.view_functions[rule.endpoint](**req.view_args)
  File "/home/giddy/Desktop/microblog/app/routes.py", line 103, in reset_password
    user = User.verify_reset_password_token(token)
AttributeError: type object 'User' has no attribute 'verify_reset_password_token'
2018-06-21 17:04:34,883 INFO: Microblog Startup [in /home/giddy/Desktop/microblog/app/__init__.py:44
2018-06-21 17:11:50,920 INFO: Microblog Startup [in /home/giddy/Desktop/microblog/app/__init__.py:44
2018-06-21 17:20:32,795 INFO: Microblog Startup [in /home/giddy/Desktop/microblog/app/__init__.py:44
2018-06-21 17:24:57,221 INFO: Microblog Startup [in /home/giddy/Desktop/microblog/app/__init__.py:44
2018-06-21 17:25:43,108 INFO: Microblog Startup [in /home/giddy/Desktop/microblog/app/__init__.py:44
2018-06-21 17:26:47,473 INFO: Microblog Startup [in /home/giddy/Desktop/microblog/app/__init__.py:44
2018-06-21 17:46:52,299 INFO: Microblog Startup [in /home/giddy/Desktop/microblog/app/__init__.py:44
2018-06-21 17:47:40,506 INFO: Microblog Startup [in /home/giddy/Desktop/microblog/app/__init__.py:44
2018-06-21 17:47:49,721 INFO: Microblog Startup [in /home/giddy/Desktop/microblog/app/__init__.py:44
2018-06-22 13:07:23,298 INFO: Microblog Startup [in /home/giddy/Desktop/microblog/app/__init__.py:44
2018-06-22 13:11:08,865 INFO: Microblog Startup [in /home/giddy/Desktop/microblog/app/__init__.py:44
2018-06-22 22:47:05,819 INFO: Microblog Startup [in /home/giddy/Desktop/microblog/app/__init__.py:46
2018-06-22 23:10:40,481 INFO: Microblog Startup [in /home/giddy/Desktop/microblog/app/__init__.py:46
2018-06-22 23:14:42,107 INFO: Microblog Startup [in /home/giddy/Desktop/microblog/app/__init__.py:46
2018-06-22 23:20:43,019 INFO: Microblog Startup [in /home/giddy/Desktop/microblog/app/__init__.py:46
2018-06-22 23:29:02,252 INFO: Microblog Startup [in /home/giddy/Desktop/microblog/app/__init__.py:46
2018-06-22 23:36:05,638 INFO: Microblog Startup [in /home/giddy/Desktop/microblog/app/__init__.py:46
